<?xml version="1.0" ?>
<!-- =================================================================================== -->
<!-- |    This document was autogenerated by xacro from matilda.xacro                  | -->
<!-- |    EDITING THIS FILE BY HAND IS NOT RECOMMENDED                                 | -->
<!-- =================================================================================== -->
<robot name="matilda" xmlns:xacro="http://ros.org/wiki/xacro">
  <!-- link list -->
  <link name="base_link">
    <visual>
      <origin rpy="0 0 0" xyz="0 0 0"/>
      <geometry>
        <mesh filename="package://matilda_support/meshes/base_link.stl"/>
      </geometry>
      <material name="matilda_grey">
        <color rgba="0.5 0.5 0.5 1"/>
      </material>
    </visual>
    <collision>
      <geometry>
        <mesh filename="package://matilda_support/meshes/base_link.stl"/>
      </geometry>
      <material name="red">
        <color rgba="1 0 0 1"/>
      </material>
    </collision>
  </link>
  <link name="link_1">
    <visual>
      <origin rpy="0 0 0" xyz="0 0 0"/>
      <geometry>
        <mesh filename="package://matilda_support/meshes/link_1.stl"/>
      </geometry>
      <material name="matilda_grey">
        <color rgba="0.5 0.5 0.5 1"/>
      </material>
    </visual>
    <collision>
      <geometry>
        <mesh filename="package://matilda_support/meshes/link_1.stl"/>
      </geometry>
      <material name="red">
        <color rgba="1 0 0 1"/>
      </material>
    </collision>
  </link>
  <link name="link_2">
    <visual>
      <origin rpy="0 0 0" xyz="0 0 0"/>
      <geometry>
        <mesh filename="package://matilda_support/meshes/link_2.stl"/>
      </geometry>
      <material name="matilda_grey">
        <color rgba="0.5 0.5 0.5 1"/>
      </material>
    </visual>
    <collision>
      <geometry>
        <mesh filename="package://matilda_support/meshes/link_2.stl"/>
      </geometry>
      <material name="red">
        <color rgba="1 0 0 1"/>
      </material>
    </collision>
  </link>
  <link name="link_3">
    <visual>
      <origin rpy="0 0 0" xyz="0 0 0"/>
      <geometry>
        <mesh filename="package://matilda_support/meshes/link_3.stl"/>
      </geometry>
      <material name="matilda_grey">
        <color rgba="0.5 0.5 0.5 1"/>
      </material>
    </visual>
    <visual>
      <origin rpy="0 0 0" xyz="0.18 0 0.027015"/>
      <geometry>
        <mesh filename="package://matilda_support/meshes/link_4_old.stl"/>
      </geometry>
      <material name="matilda_grey">
        <color rgba="0.5 0.5 0.5 1"/>
      </material>
    </visual>
    <collision>
      <geometry>
        <mesh filename="package://matilda_support/meshes/link_3.stl"/>
      </geometry>
      <material name="red">
        <color rgba="1 0 0 1"/>
      </material>
    </collision>
    <collision>
      <origin rpy="0 0 0" xyz="0.18 0 0.027015"/>
      <geometry>
        <mesh filename="package://matilda_support/meshes/link_4_old.stl"/>
      </geometry>
      <material name="red">
        <color rgba="0.5 0.5 0.5 1"/>
      </material>
    </collision>
  </link>
  <link name="link_4">
    <visual>
      <origin rpy="0 0 0" xyz="0 0 0"/>
      <geometry>
        <mesh filename="package://matilda_support/meshes/link_4.stl"/>
      </geometry>
      <material name="matilda_grey">
        <color rgba="0.5 0.5 0.5 1"/>
      </material>
    </visual>
    <collision>
      <geometry>
        <mesh filename="package://matilda_support/meshes/link_4.stl"/>
      </geometry>
      <material name="red">
        <color rgba="1 0 0 1"/>
      </material>
    </collision>
  </link>
  <link name="tool0"/>
  <link name="link_5"/>
  <link name="link_6"/>
  <!-- end of link list -->
  <!-- joint list -->
  <joint name="joint_1" type="revolute">
    <origin rpy="0 0 0" xyz="0 0 0.103"/>
    <parent link="base_link"/>
    <child link="link_1"/>
    <axis xyz="0 0 -1"/>
    <limit effort="0" lower="-2" upper="2" velocity="1.57079632679"/>
  </joint>
  <joint name="joint_2" type="revolute">
    <origin rpy="0 0 0" xyz="0.05 0 0.1"/>
    <parent link="link_1"/>
    <child link="link_2"/>
    <axis xyz="0 1 0"/>
    <limit effort="0" lower="-0.75" upper="2.5" velocity="1.57079632679"/>
  </joint>
  <joint name="joint_3" type="revolute">
    <origin rpy="0 0 0" xyz="0 0 0.615"/>
    <parent link="link_2"/>
    <child link="link_3"/>
    <axis xyz="0 -1 0"/>
    <limit effort="0" lower="-1.4" upper="1.57079632679" velocity="1.57079632679"/>
  </joint>
  <joint name="joint_4" type="revolute">
    <origin rpy="0 0 0" xyz="0.55145 0 0"/>
    <parent link="link_3"/>
    <child link="link_4"/>
    <axis xyz="0 1 0"/>
    <limit effort="0" lower="-1.57079632679" upper="1.57079632679" velocity="1.57079632679"/>
  </joint>
  <joint name="joint_4-tool0" type="fixed">
    <parent link="link_4"/>
    <child link="tool0"/>
    <origin rpy="0 1.57079632679 0" xyz="0 0 0"/>
  </joint>
  <joint name="joint_5" type="continuous">
    <parent link="tool0"/>
    <child link="link_5"/>
    <axis xyz="1 0 0"/>
    <origin rpy="0 -1.57079632679 0" xyz="0 0 0"/>
  </joint>
  <joint name="joint_6" type="continuous">
    <parent link="link_5"/>
    <child link="link_6"/>
    <axis xyz="0 0 1"/>
    <origin rpy="0 0 0" xyz="0 0 0"/>
  </joint>
  <!-- end of joint list -->
  <!-- ROS base_link to Matilda World Coordinates transform -->
  <link name="base"/>
  <joint name="base_link-base" type="fixed">
    <origin rpy="0 0 0" xyz="0 0 0"/>
    <parent link="base_link"/>
    <child link="base"/>
  </joint>
</robot>

